<mujoco model="PGI-140-80">
  <compiler angle="radian" meshdir="./gripper_mesh/"/>
  <asset>
    <mesh name="base_link" file="gripper_base_link.STL"/>
    <mesh name="finger1_link" file="finger1_link.STL"/>
    <mesh name="finger2_link" file="finger2_link.STL"/>
  </asset>
  <worldbody>
    <body name="base_link">
      <geom type="mesh" rgba="0.75294 0.75294 0.75294 1" mesh="base_link" pos="-0.0475 -0.0326 0"/>
      <body name="finger1_link" pos="0.041 0.01815 0.08">
        <joint name="finger1_joint" pos="0 0 0" axis="-1 0 0" type="slide" range="0 0.04" actuatorfrcrange="-140 140"/>
        <geom type="mesh" rgba="1 1 1 1" mesh="finger1_link" pos="-0.0485 -0.035 -0.0758"/>
      </body>
      <body name="finger2_link" pos="-0.041 -0.01815 0.08">
        <joint name="finger2_joint" pos="0 0 0" axis="1 0 0" type="slide" range="0 0.04" actuatorfrcrange="-140 140"/>
        <geom type="mesh" rgba="1 1 1 1" mesh="finger2_link" pos="-0.019 -0.012 -0.0758"/>
      </body>
    </body>
  </worldbody>
</mujoco>
