<mujoco model="rm_65_6f_description">
  <compiler angle="radian" meshdir="./65_mesh/"/>
  <asset>
    <mesh name="base_link" file="base_link.stl"/>
    <mesh name="Link1" file="Link1.stl"/>
    <mesh name="Link2" file="Link2.stl"/>
    <mesh name="Link3" file="Link3.stl"/>
    <mesh name="Link4" file="Link4.stl"/>
    <mesh name="Link5" file="Link5.stl"/>
    <mesh name="Link6" file="Link6.stl"/>
  </asset>
  <worldbody>
    <light name="top" pos="0 0 2" mode="trackcom"/>
    <geom type="plane" size="1 1 0.5" rgba= "0.8 0.8 0.8 1"/>
    <body name="Link0">
    <geom type="mesh" rgba="1 1 1 1" mesh="base_link"/>
      <body name="Link1" pos="0 0 0.2405">
        <inertial pos="2.1376e-07 0.021108 -0.025186" quat="0.988852 -0.148904 -2.81213e-05 -0.000244243" mass="0.59356" diaginertia="0.0012661 0.00124679 0.000496262"/>
        <joint name="joint1" pos="0 0 0" axis="0 0 1" range="-3.107 3.107" actuatorfrcrange="-100 100"/>
        <geom type="mesh" rgba="1 1 1 1" mesh="Link1"/>
        <body name="Link2" quat="0.499998 0.5 -0.5 0.500002">
          <inertial pos="0.15226 6.0139e-07 -0.0062025" quat="-4.62913e-07 0.800121 2.76094e-06 0.599838" mass="0.86418" diaginertia="0.00207596 0.0020527 0.00050938"/>
          <joint name="joint2" pos="0 0 0" axis="0 0 1" range="-2.269 2.269" actuatorfrcrange="-100 100"/>
          <geom type="mesh" rgba="1 1 1 1" mesh="Link2"/>
          <body name="Link3" pos="0.256 0 0" quat="0.707105 0 0 0.707108">
            <inertial pos="5.0421e-06 -0.059593 0.010569" quat="0.424679 0.564959 -0.565553 0.424993" mass="0.28963" diaginertia="0.000656041 0.00063737 0.000114619"/>
            <joint name="joint3" pos="0 0 0" axis="0 0 1" range="-2.356 2.356" actuatorfrcrange="-100 100"/>
            <geom type="mesh" rgba="1 1 1 1" mesh="Link3"/>
            <body name="Link4" pos="0 -0.21 0" quat="0.707105 0.707108 0 0">
              <inertial pos="1.1466e-06 -0.018041 -0.021541" quat="0.990405 0.138198 -6.4362e-06 9.6789e-05" mass="0.23941" diaginertia="0.00028594 0.000275321 0.000107299"/>
              <joint name="joint4" pos="0 0 0" axis="0 0 1" range="-3.107 3.107" actuatorfrcrange="-100 100"/>
              <geom type="mesh" rgba="1 1 1 1" mesh="Link4"/>
              <body name="Link5" quat="0.707105 -0.707108 0 0">
                <inertial pos="3.4542e-06 -0.059382 0.0073678" quat="0.419751 0.568643 -0.569215 0.420058" mass="0.21879" diaginertia="0.000358601 0.00035053 8.07893e-05"/>
                <joint name="joint5" pos="0 0 0" axis="0 0 1" range="-2.234 2.234" actuatorfrcrange="-100 100"/>
                <geom type="mesh" rgba="1 1 1 1" mesh="Link5"/>
                <body name="Link6" pos="0 -0.1725 0" quat="0.707105 0.707108 0 0">
                  <inertial pos="0.00032231 -0.00017819 -0.028676" quat="0.612939 0.351641 -0.613619 0.352317" mass="0.14433" diaginertia="6.1463e-05 3.68926e-05 3.38524e-05"/>
                  <joint name="joint6" pos="0 0 0" axis="0 0 1" range="-6.283 6.283" actuatorfrcrange="-100 100"/>
                  <geom type="mesh" rgba="1 1 1 1" mesh="Link6"/>
                </body>
              </body>
            </body>
          </body>
        </body>
      </body>
    </body>
  </worldbody>
</mujoco>
