<mujoco model="robot_assemble">
  <!-- <option gravity="0 0 0" /> -->
  <compiler angle="radian" meshdir="./65_mesh/"/>
  <asset>
    <mesh name="base_link" file="base_link.stl"/>
    <mesh name="Link1" file="Link1.stl"/>
    <mesh name="Link2" file="Link2.stl"/>
    <mesh name="Link3" file="Link3.stl"/>
    <mesh name="Link4" file="Link4.stl"/>
    <mesh name="Link5" file="Link5.stl"/>
    <mesh name="Link6" file="Link6.stl"/>
    <mesh name="gripper_base_link" file="gripper_base_link.STL"/>
    <mesh name="finger1_link" file="finger1_link.STL" scale="1 1 1"/>
    <mesh name="finger2_link" file="finger2_link.STL" scale="1 1 1"/>
  </asset>
  <asset>
    <material name="table_mat" specular="0" shininess="0.5" reflectance="0" rgba="0.93 0.93 0.93 1"></material>
    <mesh file="can.stl" name="can_mesh" scale="0.7 0.7 0.7" />
    <texture file="can.png" name="tex-can"/>
    <material name="coke" reflectance="0.7" texrepeat="5 5" texture="tex-can" texuniform="true"/>
  </asset>
  <worldbody>
    <light name="top" pos="0 0 2" mode="trackcom"/>
    <geom type="plane" size="1 1 0.5" rgba= "0.8 0.8 0.8 1"/>

    <body pos="0 0.5 0.5" name="table0">
			<geom size="0.25 0.3 0.5" type="box" mass="2000" material="table_mat" friction="1 0.005 0.0001" condim="3"></geom>
			<!-- <geom size="0.25 0.3 0.55" type="box" mass="2000" group="1" material="table_mat"></geom> -->
		</body>

    <!-- <body pos="-0.1 0.55 1.1" name="object0">
			<joint name="object0:joint" type="free" damping="0.01"></joint>
			<geom pos="0 0 0" mesh="can_mesh" type="mesh" solimp="0.998 0.998 0.001" solref="0.001 1" density="100" friction="0.95 0.3 0.1" material="coke" group="1" condim="4"/>
			<geom pos="0 0 0" mesh="can_mesh" type="mesh" material="coke"  conaffinity="0" contype="0" group="1" mass="0.0001"/>
			<site name="object0" pos="0 0 0" size="0.02 0.02 0.02" rgba="1 0 0 1" type="sphere"></site>
			<site rgba="0 0 0 0" size="0.005" pos="0 0 -0.06" name="can_bottom_site"/>
			<site rgba="0 0 0 0" size="0.005" pos="0 0 0.04" name="can_top_site"/>
			<site rgba="0 0 0 0" size="0.005" pos="0.025 0.025 0" name="can_horizontal_radius_site"/>
		</body> -->
    <body pos="0.1 0.4 1." name="object0">
			<joint name="object0:joint" type="free" damping="0.01"></joint>
			<geom pos="0 0 0.05" type="box" size="0.015 0.015 0.05" solimp=".8 .9 .01" solref=".02 1" friction="1.0 .05 .001" condim="6"/>
		</body>
  
    <body name="body">
      <geom type="box" pos="0 0 0.6" size="0.15 0.05 0.6" rgba="1 1 1 1"/>
      <body name="R_Link0" pos="0.02 0 1.2" quat="0.5 0.5 0.5 0.5">
        <geom type="mesh" rgba="1 1 1 1" mesh="base_link"/>
        <body name="R_Link1" pos="0 0 0.2405">
          <inertial pos="2.1376e-07 0.021108 -0.025186" quat="0.988852 -0.148904 -2.81213e-05 -0.000244243" mass="0.59356" diaginertia="0.0012661 0.00124679 0.000496262"/>
          <joint name="R_joint1" pos="0 0 0" axis="0 0 1" range="-3.107 3.107" actuatorfrcrange="-100 100" damping="100"/>
          <geom type="mesh" rgba="1 1 1 1" mesh="Link1"/>
          <body name="R_Link2" quat="7.07106781e-01 7.07106781e-01 -5.55111512e-17 5.55111512e-17">
            <inertial pos="0.15226 6.0139e-07 -0.0062025" quat="-4.62913e-07 0.800121 2.76094e-06 0.599838" mass="0.86418" diaginertia="0.00207596 0.0020527 0.00050938"/>
            <joint name="R_joint2" pos="0 0 0" axis="0 0 1" range="-0.6982 3.8398" actuatorfrcrange="-100 100" damping="100"/>
            <geom type="mesh" rgba="1 1 1 1" mesh="Link2"/>
            <body name="R_Link3" pos="0.256 0 0" quat="0.707105 0 0 0.707108">
              <inertial pos="5.0421e-06 -0.059593 0.010569" quat="0.424679 0.564959 -0.565553 0.424993" mass="0.28963" diaginertia="0.000656041 0.00063737 0.000114619"/>
              <joint name="R_joint3" pos="0 0 0" axis="0 0 1" range="-2.356 2.356" actuatorfrcrange="-100 100" damping="100"/>
              <geom type="mesh" rgba="1 1 1 1" mesh="Link3"/>
              <body name="R_Link4" pos="0 -0.21 0" quat="0.707105 0.707108 0 0">
                <inertial pos="1.1466e-06 -0.018041 -0.021541" quat="0.990405 0.138198 -6.4362e-06 9.6789e-05" mass="0.23941" diaginertia="0.00028594 0.000275321 0.000107299"/>
                <joint name="R_joint4" pos="0 0 0" axis="0 0 1" range="-3.107 3.107" actuatorfrcrange="-100 100" damping="10"/>
                <geom type="mesh" rgba="1 1 1 1" mesh="Link4"/>
                <body name="R_Link5" quat="0.707105 -0.707108 0 0">
                  <inertial pos="3.4542e-06 -0.059382 0.0073678" quat="0.419751 0.568643 -0.569215 0.420058" mass="0.21879" diaginertia="0.000358601 0.00035053 8.07893e-05"/>
                  <joint name="R_joint5" pos="0 0 0" axis="0 0 1" range="-2.234 2.234" actuatorfrcrange="-100 100" damping="10"/>
                  <geom type="mesh" rgba="1 1 1 1" mesh="Link5"/>
                  <body name="R_Link6" pos="0 -0.1725 0" quat="0.707105 0.707108 0 0">
                    <inertial pos="0.00032231 -0.00017819 -0.028676" quat="0.612939 0.351641 -0.613619 0.352317" mass="0.14433" diaginertia="6.1463e-05 3.68926e-05 3.38524e-05"/>
                    <joint name="R_joint6" pos="0 0 0" axis="0 0 1" range="-6.283 6.283" actuatorfrcrange="-100 100" damping="10"/>
                    <geom type="mesh" rgba="1 1 1 1" mesh="Link6"/>
                    <body name="R_gripper_base_link">
                      <geom type="mesh" rgba="0.75294 0.75294 0.75294 1" mesh="gripper_base_link" pos="-0.0475 -0.0326 0" conaffinity="0" contype="0"/>
                      <body name="R_finger1_link" pos="0.041 0.01815 0.08">
                        <joint name="R_finger1_joint" pos="0 0 0" axis="-1 0 0" type="slide" range="0 0.04" actuatorfrcrange="-140 140" damping="100" armature="5"/>
                        <geom type="mesh" rgba="1 1 1 1" mesh="finger1_link" pos="-0.0485 -0.035 -0.0758" conaffinity="1" contype="0" friction="1 0.5 0.0001" solref="0.01 1" solimp="0.8 0.9 0.001" condim="6"/>
                      </body>
                      <body name="R_finger2_link" pos="-0.041 -0.01815 0.08">
                        <joint name="R_finger2_joint" pos="0 0 0" axis="1 0 0" type="slide" range="0 0.04" actuatorfrcrange="-140 140" damping="100" armature="5"/>
                        <geom type="mesh" rgba="1 1 1 1" mesh="finger2_link" pos="-0.019 -0.012 -0.0758" conaffinity="1" contype="0" friction="1 0.5 0.0001" solref="0.01 1" solimp="0.8 0.9 0.001" condim="6"/>
                      </body>
                    </body>
                  </body>
                </body>
              </body>
            </body>
          </body>
        </body>
      </body>
      <body name="L_Link0" pos="-0.02 0 1.2" quat="0.5 -0.5 -0.5 0.5">
        <geom type="mesh" rgba="1 1 1 1" mesh="base_link"/>
        <body name="L_Link1" pos="0 0 0.2405">
          <inertial pos="2.1376e-07 0.021108 -0.025186" quat="0.988852 -0.148904 -2.81213e-05 -0.000244243" mass="0.59356" diaginertia="0.0012661 0.00124679 0.000496262"/>
          <joint name="L_joint1" pos="0 0 0" axis="0 0 1" range="-3.107 3.107" actuatorfrcrange="-100 100" damping="100"/>
          <geom type="mesh" rgba="1 1 1 1" mesh="Link1"/>
          <body name="L_Link2" quat="7.07106781e-01 7.07106781e-01 -5.55111512e-17 5.55111512e-17">
            <inertial pos="0.15226 6.0139e-07 -0.0062025" quat="-4.62913e-07 0.800121 2.76094e-06 0.599838" mass="0.86418" diaginertia="0.00207596 0.0020527 0.00050938"/>
            <joint name="L_joint2" pos="0 0 0" axis="0 0 1" range="-0.6982 3.8398" actuatorfrcrange="-100 100" damping="100"/>
            <geom type="mesh" rgba="1 1 1 1" mesh="Link2"/>
            <body name="L_Link3" pos="0.256 0 0" quat="0.707105 0 0 0.707108">
              <inertial pos="5.0421e-06 -0.059593 0.010569" quat="0.424679 0.564959 -0.565553 0.424993" mass="0.28963" diaginertia="0.000656041 0.00063737 0.000114619"/>
              <joint name="L_joint3" pos="0 0 0" axis="0 0 1" range="-2.356 2.356" actuatorfrcrange="-100 100" damping="100"/>
              <geom type="mesh" rgba="1 1 1 1" mesh="Link3"/>
              <body name="L_Link4" pos="0 -0.21 0" quat="0.707105 0.707108 0 0">
                <inertial pos="1.1466e-06 -0.018041 -0.021541" quat="0.990405 0.138198 -6.4362e-06 9.6789e-05" mass="0.23941" diaginertia="0.00028594 0.000275321 0.000107299"/>
                <joint name="L_joint4" pos="0 0 0" axis="0 0 1" range="-3.107 3.107" actuatorfrcrange="-100 100" damping="10"/>
                <geom type="mesh" rgba="1 1 1 1" mesh="Link4"/>
                <body name="L_Link5" quat="0.707105 -0.707108 0 0">
                  <inertial pos="3.4542e-06 -0.059382 0.0073678" quat="0.419751 0.568643 -0.569215 0.420058" mass="0.21879" diaginertia="0.000358601 0.00035053 8.07893e-05"/>
                  <joint name="L_joint5" pos="0 0 0" axis="0 0 1" range="-2.234 2.234" actuatorfrcrange="-100 100" damping="10"/>
                  <geom type="mesh" rgba="1 1 1 1" mesh="Link5"/>
                  <body name="L_Link6" pos="0 -0.1725 0" quat="0.707105 0.707108 0 0">
                    <inertial pos="0.00032231 -0.00017819 -0.028676" quat="0.612939 0.351641 -0.613619 0.352317" mass="0.14433" diaginertia="6.1463e-05 3.68926e-05 3.38524e-05"/>
                    <joint name="L_joint6" pos="0 0 0" axis="0 0 1" range="-6.283 6.283" actuatorfrcrange="-100 100" damping="10"/>
                    <geom type="mesh" rgba="1 1 1 1" mesh="Link6"/>
                    <body name="L_gripper_base_link">
                      <geom type="mesh" rgba="0.75294 0.75294 0.75294 1" mesh="gripper_base_link" pos="-0.0475 -0.0326 0"/>
                      <body name="L_finger1_link" pos="0.041 0.01815 0.08">
                        <joint name="L_finger1_joint" pos="0 0 0" axis="-1 0 0" type="slide" range="0 0.04" actuatorfrcrange="-140 140" damping="100" armature="5"/>
                        <geom type="mesh" rgba="1 1 1 1" mesh="finger1_link" pos="-0.0485 -0.035 -0.0758" conaffinity="1" contype="0" friction="1 0.5 0.0001" solref="0.01 1" solimp="0.8 0.9 0.001" condim="6"/>
                      </body>
                      <body name="L_finger2_link" pos="-0.041 -0.01815 0.08">
                        <joint name="L_finger2_joint" pos="0 0 0" axis="1 0 0" type="slide" range="0 0.04" actuatorfrcrange="-140 140" damping="100" armature="5"/>
                        <geom type="mesh" rgba="1 1 1 1" mesh="finger2_link" pos="-0.019 -0.012 -0.0758" conaffinity="1" contype="0" friction="1 0.5 0.0001" solref="0.01 1" solimp="0.8 0.9 0.001" condim="6"/>
                      </body>
                    </body>
                  </body>
                </body>
              </body>
            </body>
          </body>
        </body>
      </body>
    </body>
  </worldbody>
  <actuator>
    <position name="R_joint1" joint="R_joint1" kp="870" forcerange="-100 100" ctrlrange="-3.107 3.107" user="-2.9671 2.9671 2.1750 0.1 0.1"/>
    <position name="R_joint2" joint="R_joint2" kp="870" forcerange="-100 100" ctrlrange="-0.6982 3.8398" user="-1.8326 1.8326 2.1750 0.1 0.1"/>
    <position name="R_joint3" joint="R_joint3" kp="870" forcerange="-100 100" ctrlrange="-2.356 2.356" user="-3.1416 0.0 2.1750 0.1 0.1"/>
    <position name="R_joint4" joint="R_joint4" kp="120" forcerange="-100 100" ctrlrange="-3.107 3.107" user="-2.9671 2.9671 2.6100 0.1 0.1"/>
    <position name="R_joint5" joint="R_joint5" kp="120" forcerange="-100 100" ctrlrange="-2.234 2.234" user="-3.7525 2.1817 2.6100 0.1 0.1"/>
    <position name="R_joint6" joint="R_joint6" kp="120" forcerange="-100 100" ctrlrange="-6.283 6.283" user="-2.9671 2.9671 2.6100 0.1 0.1"/>
    <position name="R_finger1_joint" joint="R_finger1_joint" kp="500" forcerange="-140 140" ctrlrange="0 0.04" user="0 0.04 0.2 0.1 0.1"/>
    <position name="R_finger2_joint" joint="R_finger2_joint" kp="500" forcerange="-140 140" ctrlrange="0 0.04" user="0 0.04 0.2 0.1 0.1"/>
    <position name="L_joint1" joint="L_joint1" kp="870" forcerange="-100 100" ctrlrange="-3.107 3.107" user="-2.9671 2.9671 2.1750 0.1 0.1"/>
    <position name="L_joint2" joint="L_joint2" kp="870" forcerange="-100 100" ctrlrange="-0.6982 3.8398" user="-1.8326 1.8326 2.1750 0.1 0.1"/>
    <position name="L_joint3" joint="L_joint3" kp="870" forcerange="-100 100" ctrlrange="-2.356 2.356" user="-3.1416 0.0 2.1750 0.1 0.1"/>
    <position name="L_joint4" joint="L_joint4" kp="120" forcerange="-100 100" ctrlrange="-3.107 3.107" user="-2.9671 2.9671 2.6100 0.1 0.1"/>
    <position name="L_joint5" joint="L_joint5" kp="120" forcerange="-100 100" ctrlrange="-2.234 2.234" user="-3.7525 2.1817 2.6100 0.1 0.1"/>
    <position name="L_joint6" joint="L_joint6" kp="120" forcerange="-100 100" ctrlrange="-6.283 6.283" user="-2.9671 2.9671 2.6100 0.1 0.1"/>
    <position name="L_finger1_joint" joint="L_finger1_joint" kp="500" forcerange="-140 140" ctrlrange="0 0.04" user="0 0.04 0.2 0.1 0.1"/>
    <position name="L_finger2_joint" joint="L_finger2_joint" kp="500" forcerange="-140 140" ctrlrange="0 0.04" user="0 0.04 0.2 0.1 0.1"/>
  </actuator>
</mujoco>
